Workbook

Sheet Summary
A1: Summary
A3: Key Output | H3: Note
C4: Debt sizing
D5: =Model!D141 -> Target debt size | E5: =Model!E141 -> 1.3182507e+08 | F5: AUD | H5: The DSCR sized debt represents ~60% of total project cost (57.7% of total project cost & IDC), which are both lower than the 60% expectation
C7: Key metrics and returns
D8: =Model!D181 -> Min. DSCR | E8: =Model!E181 -> 1.3499743
D9: =Model!D182 -> Average DSCR | E9: =Model!E182 -> 1.3631561
D10: =Model!D190 -> LLCR | E10: =Model!E190 -> 1.2296298
D11: P-IRR | E11: =Model!E236 -> 0.03859863 | H11: P-IRR (3.9%) is low due to the interest tax shield. The levered entity generates a NOL pool from Years 1–5 interest deductions, deferring tax payments through Year 20. On an unlevered basis, tax is payable from Year 1 with no carry-forward, reducing early-year cash flows. The spread represents the timing value of the tax shield, not project underperformance.
D12: =Model!D245 -> Debt IRR | E12: =Model!E245 -> 0.06492596
D13: =Model!D251 -> Equity IRR | E13: =Model!E251 -> 0.041328928 | H13: E-IRR suppressed at 4.1% due to no refi modelled at mini-perm maturity. Dividends commence Year 14. True E-IRR contingent on refinancing terms.
F14: PPA Price | G14: Merchant Price (2028)
D15: Breakeven price factor | E15: 0.80982037 | F15: =75*$E15 -> 60.736528 | G15: =55*E15 -> 44.54012 | H15: adjusted in Input!E32
C17: Merchant exposure
D18: =Model!D299 -> Merchant Intensity | E18: =Model!E299 -> 0.54149555

Sheet Sensitivity
A1: Sensitivity
D2: Sensitivities | L2: Methodology
D3: Scenario | E3: Debt size (AUD) | F3: Min.DSCR | G3: Avg DSCR | H3: LLCR | I3: P-IRR | J3: D-IRR | K3: E-IRR
D4: Base (Live) | E4: =Summary!E5 -> 1.3182507e+08 | F4: =Summary!E8 -> 1.3499743 | G4: =Summary!E9 -> 1.3631561 | H4: =Summary!E10 -> 1.2296298 | I4: =Summary!E11 -> 0.03859863 | J4: =Summary!E12 -> 0.06492596 | K4: =Summary!E13 -> 0.041328928
D5: Spot -15% | E5: 1.2405967e+08 | F5: 1.3497696 | G5: 1.3667281 | H5: 1.1681431 | I5: 0.027703962 | J5: 0.064925942 | K5: 0.026049086 | L5: Spot price (2028) * 0.85
D6: P90 generation | E6: 1.1391635e+08 | F6: 1.3492499 | G6: 1.3660112 | H6: 1.240056 | I6: 0.028936651 | J6: 0.064925948 | K6: 0.027582631 | L6: Net capacity factor * 0.9
D7: Curtailment +5% | E7: 1.2908542e+08 | F7: 1.3500616 | G7: 1.3645194 | H7: 1.209595 | I7: 0.035012767 | J7: 0.064925954 | K7: 0.036205831 | L7: Negative pricing co-efficient +5%
D8: OPEX +10% | E8: 1.2702305e+08 | F8: 1.3501302 | G8: 1.3665349 | H8: 1.2269927 | I8: 0.035432938 | J8: 0.064925948 | K8: 0.03667089 | L8: Fixed OPEX * 1.1
D9: MLF 0.82 | E9: 1.1959055e+08 | F9: 1.3497751 | G9: 1.365286 | H9: 1.2370956 | I9: 0.03211976 | J9: 0.064925948 | K9: 0.031888893 | L9: MLF = 0.82
D10: Interest + 1% | E10: 1.2046748e+08 | F10: 1.3499739 | G10: 1.3631556 | H10: 1.2400459 | I10: 0.03846958 | J10: 0.074914005 | K10: 0.038653979 | L10: Interest rate + 1%

Sheet Input
A1: Input
A2: Assumption | E2: Input | F2: Input | G2: Unit | H2: Note
A3: Dates
D4: Financial Close | E4: =DATE(2026,12,31) -> 46387 | G4: date
D5: Construction | E5: 12 | G5: months | H5: straight line capex spend in 2027
D6: Commercial Operation | E6: =EOMONTH(E4 - 1, E5) + 1 -> 46753 | G6: date
D7: Operation | E7: 35 | G7: years
D8: Decommissioning | E8: =EOMONTH(E6 - 1, E7 * 12) -> 59536 | G8: date
A10: Generation
D11: Installed capacity | E11: 200 | G11: MWdc | H11: as per page 1
D12: Installed capacity | E12: 160 | G12: MWac | H12: as per page 1
D13: Net capacity factor (P50) | E13: 0.24
D14: Degradation | E14: 0.005 | G14: p.a. | H14: compounding from year 2
D15: Marginal Loss Factor (MLF) | E15: 0.88 | H15: static for the project life
A17: Capital Cost
D18: Total EPC & connection cost | E18: 220000000 | G18: AUD
D19: Total project cost | E19: =SUM(E18:E18) -> 220000000 | G19: AUD
D21: Useful life | E21: 20 | G21: years
A23: Construction loan
E24: Debt | F24: Equity
D25: Funding source | E25: 65 | F25: 35 | G25: %
D26: Gearing ratio (D/C) | E26: =E25/SUM(E25:F25) -> 0.65
D27: Construction loan facility | E27: =E19*E26 -> 143000000 | G27: AUD
D28: Equity contribution | E28: =E19-E27 -> 77000000 | G28: AUD
A30: Revenue
D31: =Summary!D15 -> Breakeven price factor | E31: 1 | H31: affects PPA price and Spot price (2028)
B33: Contracted revenue
D34: Volume | E34: 0.65
D35: PPA price | E35: =E31*75 -> 75 | G35: AUD/MWh | H35: no escalation
D36: PPA tenor | E36: 10 | G36: years
B38: Spot revenue
D39: Volume | E39: =1-E34 -> 0.35
D40: Spot price (2028) | E40: =E31*55 -> 55 | G40: AUD/MWh
D41: Spot price escalation | E41: 0.02 | G41: p.a.
D42: Negative pricing co-efficient | E42: 0.05 | H42: 5% of merchant volume is lost / curtailed due to negative prices (ie. no revenue)
A44: Operational Expense
D45: Fixed OPEX & AEMO fees (per MWac) | E45: 30000 | G45: AUD/MWac/yr
D46: Fixed OPEX & AEMO fees | E46: =E45*E12 -> 4800000 | G46: AUD/yr
D47: Operating expense escalation | E47: 0.025 | G47: p.a. | H47: compounding from year 2
C49: Working Capital
...

Sheet Model
A1: Model
D2: Months per period | E2: 12
D3: Period number | K3: 1 | L3: =K3+1 -> 2 | M3: =L3+1 -> 3 | N3: =M3+1 -> 4 | O3: =N3+1 -> 5 | P3: =O3+1 -> 6 | Q3: =P3+1 -> 7 | R3: =Q3+1 -> 8 | S3: =R3+1 -> 9 | ... AU3: =AT3+1 -> 37
D4: BoP | K4: =J5+1 -> 46388 | L4: =K5+1 -> 46753 | M4: =L5+1 -> 47119 | N4: =M5+1 -> 47484 | O4: =N5+1 -> 47849 | P4: =O5+1 -> 48214 | Q4: =P5+1 -> 48580 | R4: =Q5+1 -> 48945 | ... AU4: =AT5+1 -> 59537
D5: EoP | J5: =Input!E4 -> 46387 | K5: =EOMONTH(K4-1, $E$2) -> 46752 | L5: =EOMONTH(L4-1, $E$2) -> 47118 | M5: =EOMONTH(M4-1, $E$2) -> 47483 | N5: =EOMONTH(N4-1, $E$2) -> 47848 | O5: =EOMONTH(O4-1, $E$2) -> 48213 | P5: =EOMONTH(P4-1, $E$2) -> 48579 | Q5: =EOMONTH(Q4-1, $E$2) -> 48944 | R5: =EOMONTH(R4-1, $E$2) -> 49309 | ... AU5: =EOMONTH(AU4-1, $E$2) -> 59901
D6: Year | K6: =YEAR(K4) -> 2027 | L6: =YEAR(L4) -> 2028 | M6: =YEAR(M4) -> 2029 | N6: =YEAR(N4) -> 2030 | O6: =YEAR(O4) -> 2031 | P6: =YEAR(P4) -> 2032 | Q6: =YEAR(Q4) -> 2033 | R6: =YEAR(R4) -> 2034 | ... AU6: =YEAR(AU4) -> 2063
E7: Assumption | F7: Assumption | G7: Date | H7: Date | I7: Unit | J7: Sum
A8: Timing
D9: COD flag | G9: =Input!E6 -> 46753 | K9: =($G9=K$4)*1 -> 0 | L9: =($G9=L$4)*1 -> 1 | M9: =($G9=M$4)*1 -> 0 | N9: =($G9=N$4)*1 -> 0 | O9: =($G9=O$4)*1 -> 0 | P9: =($G9=P$4)*1 -> 0 | Q9: =($G9=Q$4)*1 -> 0 | R9: =($G9=R$4)*1 -> 0 | ... AU9: =($G9=AU$4)*1 -> 0
D10: Years of operation | E10: =Input!E7 -> 35 | I10: years
D11: PPA Life | E11: =Input!E36 -> 10 | I11: years
D13: Construction period flag | G13: =Input!E4+1 -> 46388 | H13: =G9-1 -> 46752 | K13: =AND(K$4>=$G13, K$5<=$H13) * 1 -> 1 | L13: =AND(L$4>=$G13, L$5<=$H13) * 1 -> 0 | M13: =AND(M$4>=$G13, M$5<=$H13) * 1 -> 0 | N13: =AND(N$4>=$G13, N$5<=$H13) * 1 -> 0 | O13: =AND(O$4>=$G13, O$5<=$H13) * 1 -> 0 | P13: =AND(P$4>=$G13, P$5<=$H13) * 1 -> 0 | Q13: =AND(Q$4>=$G13, Q$5<=$H13) * 1 -> 0 | R13: =AND(R$4>=$G13, R$5<=$H13) * 1 -> 0 | ... AU13: =AND(AU$4>=$G13, AU$5<=$H13) * 1 -> 0
D14: Operating period flag | G14: =G9 -> 46753 | H14: =EOMONTH(G14 - 1, E10 * 12) -> 59536 | K14: =AND(K$4>=$G14, K$5<=$H14) * 1 -> 0 | L14: =AND(L$4>=$G14, L$5<=$H14) * 1 -> 1 | M14: =AND(M$4>=$G14, M$5<=$H14) * 1 -> 1 | N14: =AND(N$4>=$G14, N$5<=$H14) * 1 -> 1 | O14: =AND(O$4>=$G14, O$5<=$H14) * 1 -> 1 | P14: =AND(P$4>=$G14, P$5<=$H14) * 1 -> 1 | Q14: =AND(Q$4>=$G14, Q$5<=$H14) * 1 -> 1 | R14: =AND(R$4>=$G14, R$5<=$H14) * 1 -> 1 | ... AU14: =AND(AU$4>=$G14, AU$5<=$H14) * 1 -> 0
D15: PPA period flag | G15: =G9 -> 46753 | H15: =EOMONTH(G15 - 1, E11 * 12) -> 50405 | K15: =AND(K$4>=$G15, K$5<=$H15) * 1 -> 0 | L15: =AND(L$4>=$G15, L$5<=$H15) * 1 -> 1 | M15: =AND(M$4>=$G15, M$5<=$H15) * 1 -> 1 | N15: =AND(N$4>=$G15, N$5<=$H15) * 1 -> 1 | O15: =AND(O$4>=$G15, O$5<=$H15) * 1 -> 1 | P15: =AND(P$4>=$G15, P$5<=$H15) * 1 -> 1 | Q15: =AND(Q$4>=$G15, Q$5<=$H15) * 1 -> 1 | R15: =AND(R$4>=$G15, R$5<=$H15) * 1 -> 1 | ... AU15: =AND(AU$4>=$G15, AU$5<=$H15) * 1 -> 0
D17: Operating period counter | K17: =J17+K14 -> 0 | L17: =K17+L14 -> 1 | M17: =L17+M14 -> 2 | N17: =M17+N14 -> 3 | O17: =N17+O14 -> 4 | P17: =O17+P14 -> 5 | Q17: =P17+Q14 -> 6 | R17: =Q17+R14 -> 7 | ... AU17: =AT17+AU14 -> 35
A19: Operation
D20: =D$9 -> COD flag | K20: =K$9 -> 0 | L20: =L$9 -> 1 | M20: =M$9 -> 0 | N20: =N$9 -> 0 | O20: =O$9 -> 0 | P20: =P$9 -> 0 | Q20: =Q$9 -> 0 | R20: =R$9 -> 0 | ... AU20: =AU$9 -> 0
D21: =D$14 -> Operating period flag | K21: =K$14 -> 0 | L21: =L$14 -> 1 | M21: =M$14 -> 1 | N21: =N$14 -> 1 | O21: =O$14 -> 1 | P21: =P$14 -> 1 | Q21: =Q$14 -> 1 | R21: =R$14 -> 1 | ... AU21: =AU$14 -> 0
D22: =D$15 -> PPA period flag | K22: =K$15 -> 0 | L22: =L$15 -> 1 | M22: =M$15 -> 1 | N22: =N$15 -> 1 | O22: =O$15 -> 1 | P22: =P$15 -> 1 | Q22: =Q$15 -> 1 | R22: =R$15 -> 1 | ... AU22: =AU$15 -> 0
B24: Revenue
C25: Volume
D26: =Input!D12 -> Installed capacity | E26: =Input!E12 -> 160 | I26: MWac | K26: =$E26 -> 160 | L26: =$E26 -> 160 | M26: =$E26 -> 160 | N26: =$E26 -> 160 | O26: =$E26 -> 160 | P26: =$E26 -> 160 | Q26: =$E26 -> 160 | R26: =$E26 -> 160 | ... AU26: =$E26 -> 160
D27: Net Capacity Factor | E27: =Input!E13 -> 0.24 | K27: =$E27 -> 0.24 | L27: =$E27 -> 0.24 | M27: =$E27 -> 0.24 | N27: =$E27 -> 0.24 | O27: =$E27 -> 0.24 | P27: =$E27 -> 0.24 | Q27: =$E27 -> 0.24 | R27: =$E27 -> 0.24 | ... AU27: =$E27 -> 0.24
D28: Hours per period | E28: =365*24 -> 8760 | I28: hrs | K28: =$E28 -> 8760 | L28: =$E28 -> 8760 | M28: =$E28 -> 8760 | N28: =$E28 -> 8760 | O28: =$E28 -> 8760 | P28: =$E28 -> 8760 | Q28: =$E28 -> 8760 | R28: =$E28 -> 8760 | ... AU28: =$E28 -> 8760
D29: Gross generation | I29: MWh | K29: =K26*K27*K28 * K21 -> 0 | L29: =L26*L27*L28 * L21 -> 336384 | M29: =M26*M27*M28 * M21 -> 336384 | N29: =N26*N27*N28 * N21 -> 336384 | O29: =O26*O27*O28 * O21 -> 336384 | P29: =P26*P27*P28 * P21 -> 336384 | Q29: =Q26*Q27*Q28 * Q21 -> 336384 | R29: =R26*R27*R28 * R21 -> 336384 | ... AU29: =AU26*AU27*AU28 * AU21 -> 0
D31: =Input!D14 -> Degradation | E31: =Input!E14 -> 0.005 | K31: =$E31*K21 -> 0 | L31: =$E31*L21 -> 0.005 | M31: =$E31*M21 -> 0.005 | N31: =$E31*N21 -> 0.005 | O31: =$E31*O21 -> 0.005 | P31: =$E31*P21 -> 0.005 | Q31: =$E31*Q21 -> 0.005 | R31: =$E31*R21 -> 0.005 | ... AU31: =$E31*AU21 -> 0
D32: Degradation factor | K32: =IF(K$20=1, 1, J32*(1-K31)) -> 0 | L32: =IF(L$20=1, 1, K32*(1-L31)) -> 1 | M32: =IF(M$20=1, 1, L32*(1-M31)) -> 0.995 | N32: =IF(N$20=1, 1, M32*(1-N31)) -> 0.990025 | O32: =IF(O$20=1, 1, N32*(1-O31)) -> 0.98507488 | P32: =IF(P$20=1, 1, O32*(1-P31)) -> 0.9801495 | Q32: =IF(Q$20=1, 1, P32*(1-Q31)) -> 0.97524875 | R32: =IF(R$20=1, 1, Q32*(1-R31)) -> 0.97037251 | ... AU32: =IF(AU$20=1, 1, AT32*(1-AU31)) -> 0.84330514
D33: =Input!D15 -> Marginal Loss Factor (MLF) | E33: =Input!E15 -> 0.88 | K33: =$E33 -> 0.88 | L33: =$E33 -> 0.88 | M33: =$E33 -> 0.88 | N33: =$E33 -> 0.88 | O33: =$E33 -> 0.88 | P33: =$E33 -> 0.88 | Q33: =$E33 -> 0.88 | R33: =$E33 -> 0.88 | ... AU33: =$E33 -> 0.88
D34: Net generation | I34: MWh | K34: =K29*K32*K33 -> 0 | L34: =L29*L32*L33 -> 296017.92 | M34: =M29*M32*M33 -> 294537.83 | N34: =N29*N32*N33 -> 293065.14 | O34: =O29*O32*O33 -> 291599.82 | P34: =P29*P32*P33 -> 290141.82 | Q34: =Q29*Q32*Q33 -> 288691.11 | R34: =R29*R32*R33 -> 287247.65 | ... AU34: =AU29*AU32*AU33 -> 0
C36: Price
D37: PPA
D38: Contracted volume | E38: =Input!E34 -> 0.65 | I38: MWh | K38: =K$34*$E38*K22 -> 0 | L38: =L$34*$E38*L22 -> 192411.65 | M38: =M$34*$E38*M22 -> 191449.59 | N38: =N$34*$E38*N22 -> 190492.34 | O38: =O$34*$E38*O22 -> 189539.88 | P38: =P$34*$E38*P22 -> 188592.18 | Q38: =Q$34*$E38*Q22 -> 187649.22 | R38: =R$34*$E38*R22 -> 186710.97 | ... AU38: =AU$34*$E38*AU22 -> 0
D39: =Input!D35 -> PPA price | E39: =Input!E35 -> 75 | I39: AUD/MWh | K39: =$E39*K22 -> 0 | L39: =$E39*L22 -> 75 | M39: =$E39*M22 -> 75 | N39: =$E39*N22 -> 75 | O39: =$E39*O22 -> 75 | P39: =$E39*P22 -> 75 | Q39: =$E39*Q22 -> 75 | R39: =$E39*R22 -> 75 | ... AU39: =$E39*AU22 -> 0
D40: Total PPA revenue | I40: AUD | K40: =K38*K39 -> 0 | L40: =L38*L39 -> 14430874 | M40: =M38*M39 -> 14358719 | N40: =N38*N39 -> 14286926 | O40: =O38*O39 -> 14215491 | P40: =P38*P39 -> 14144414 | Q40: =Q38*Q39 -> 14073691 | R40: =R38*R39 -> 14003323 | ... AU40: =AU38*AU39 -> 0
D42: Merchant
D43: Merchant volume | I43: MWh | K43: =K34-K38 -> 0 | L43: =L34-L38 -> 103606.27 | M43: =M34-M38 -> 103088.24 | N43: =N34-N38 -> 102572.8 | O43: =O34-O38 -> 102059.94 | P43: =P34-P38 -> 101549.64 | Q43: =Q34-Q38 -> 101041.89 | R43: =R34-R38 -> 100536.68 | ... AU43: =AU34-AU38 -> 0
D44: =Input!D40 -> Spot price (2028) | E44: =Input!E40 -> 55 | I44: AUD/MWh | K44: =$E44 -> 55 | L44: =$E44 -> 55 | M44: =$E44 -> 55 | N44: =$E44 -> 55 | O44: =$E44 -> 55 | P44: =$E44 -> 55 | Q44: =$E44 -> 55 | R44: =$E44 -> 55 | ... AU44: =$E44 -> 55
D45: =Input!D41 -> Spot price escalation | E45: =Input!E41 -> 0.02 | K45: =$E45 -> 0.02 | L45: =$E45 -> 0.02 | M45: =$E45 -> 0.02 | N45: =$E45 -> 0.02 | O45: =$E45 -> 0.02 | P45: =$E45 -> 0.02 | Q45: =$E45 -> 0.02 | R45: =$E45 -> 0.02 | ... AU45: =$E45 -> 0.02
D46: Escalation factor | K46: =IF(K$20=1, 1, J46*(1+K45)) -> 0 | L46: =IF(L$20=1, 1, K46*(1+L45)) -> 1 | M46: =IF(M$20=1, 1, L46*(1+M45)) -> 1.02 | N46: =IF(N$20=1, 1, M46*(1+N45)) -> 1.0404 | O46: =IF(O$20=1, 1, N46*(1+O45)) -> 1.061208 | P46: =IF(P$20=1, 1, O46*(1+P45)) -> 1.0824322 | Q46: =IF(Q$20=1, 1, P46*(1+Q45)) -> 1.1040808 | R46: =IF(R$20=1, 1, Q46*(1+R45)) -> 1.1261624 | ... AU46: =IF(AU$20=1, 1, AT46*(1+AU45)) -> 1.9998896
D47: =Input!D42 -> Negative pricing co-efficient | E47: =Input!E42 -> 0.05 | K47: =$E47 -> 0.05 | L47: =$E47 -> 0.05 | M47: =$E47 -> 0.05 | N47: =$E47 -> 0.05 | O47: =$E47 -> 0.05 | P47: =$E47 -> 0.05 | Q47: =$E47 -> 0.05 | R47: =$E47 -> 0.05 | ... AU47: =$E47 -> 0.05
...

Sheet FS
A1: Financial Statements
D2: Year | F2: =Model!K6 -> 2027 | G2: =Model!L6 -> 2028 | H2: =Model!M6 -> 2029 | I2: =Model!N6 -> 2030 | J2: =Model!O6 -> 2031 | K2: =Model!P6 -> 2032 | L2: =Model!Q6 -> 2033 | M2: =Model!R6 -> 2034 | ... AP2: =Model!AU6 -> 2063
E3: Unit
A4: Income Statement
D5: =Model!D81 -> Total Revenue | E5: AUD | F5: =Model!K81 -> 0 | G5: =Model!L81 -> 19844301 | H5: =Model!M81 -> 19852807 | I5: =Model!N81 -> 19862875 | J5: =Model!O81 -> 19874522 | K5: =Model!P81 -> 19887764 | L5: =Model!Q81 -> 19902618 | M5: =Model!R81 -> 19919101 | ... AP5: =Model!AU81 -> 0
D6: =Model!D82 -> Operating expense | E6: AUD | F6: =Model!K82 -> 0 | G6: =Model!L82 -> -4800000 | H6: =Model!M82 -> -4920000 | I6: =Model!N82 -> -5043000 | J6: =Model!O82 -> -5169075 | K6: =Model!P82 -> -5298301.9 | L6: =Model!Q82 -> -5430759.4 | M6: =Model!R82 -> -5566528.4 | ... AP6: =Model!AU82 -> 0
D7: =Model!D83 -> EBITDA | E7: AUD | F7: =Model!K83 -> 0 | G7: =Model!L83 -> 15044301 | H7: =Model!M83 -> 14932807 | I7: =Model!N83 -> 14819875 | J7: =Model!O83 -> 14705447 | K7: =Model!P83 -> 14589463 | L7: =Model!Q83 -> 14471859 | M7: =Model!R83 -> 14352572 | ... AP7: =Model!AU83 -> 0
D8: =Model!D84 -> % of revenue | F8: =Model!K84 -> 0 | G8: =Model!L84 -> 0.75811696 | H8: =Model!M84 -> 0.7521761 | I8: =Model!N84 -> 0.74610927 | J8: =Model!O84 -> 0.7399145 | K8: =Model!P84 -> 0.73358987 | L8: =Model!Q84 -> 0.72713342 | M8: =Model!R84 -> 0.72054319 | ... AP8: =Model!AU84 -> 0
D9: =Model!D85 -> Depreciation expense | E9: AUD | F9: =Model!K85 -> 0 | G9: =Model!L85 -> -11428431 | H9: =Model!M85 -> -11428431 | I9: =Model!N85 -> -11428431 | J9: =Model!O85 -> -11428431 | K9: =Model!P85 -> -11428431 | L9: =Model!Q85 -> -11428431 | M9: =Model!R85 -> -11428431 | ... AP9: =Model!AU85 -> 0
D10: =Model!D86 -> EBIT | E10: AUD | F10: =Model!K86 -> 0 | G10: =Model!L86 -> 3615869.8 | H10: =Model!M86 -> 3504375.5 | I10: =Model!N86 -> 3391443.8 | J10: =Model!O86 -> 3277015.9 | K10: =Model!P86 -> 3161031.1 | L10: =Model!Q86 -> 3043427.4 | M10: =Model!R86 -> 2924141 | ... AP10: =Model!AU86 -> 0
D11: =Model!D87 -> % of revenue | F11: =Model!K87 -> 0 | G11: =Model!L87 -> 0.182212 | H11: =Model!M87 -> 0.17651789 | I11: =Model!N87 -> 0.17074284 | J11: =Model!O87 -> 0.16488526 | K11: =Model!P87 -> 0.15894351 | L11: =Model!Q87 -> 0.15291593 | M11: =Model!R87 -> 0.14680085 | ... AP11: =Model!AU87 -> 0
D12: =Model!D88 -> Interest expense | E12: AUD | F12: =Model!K88 -> 0 | G12: =Model!L88 -> -8568629.8 | H12: =Model!M88 -> -8147711.2 | I12: =Model!N88 -> -7706680 | J12: =Model!O88 -> -7244322.3 | K12: =Model!P88 -> -6759349.1 | L12: =Model!Q88 -> 0 | M12: =Model!R88 -> 0 | ... AP12: =Model!AU88 -> 0
D13: =Model!D89 -> Profit before tax | E13: AUD | F13: =Model!K89 -> 0 | G13: =Model!L89 -> -4952760 | H13: =Model!M89 -> -4643335.7 | I13: =Model!N89 -> -4315236.1 | J13: =Model!O89 -> -3967306.4 | K13: =Model!P89 -> -3598318 | L13: =Model!Q89 -> 3043427.4 | M13: =Model!R89 -> 2924141 | ... AP13: =Model!AU89 -> 0
D14: =Model!D98 -> Tax expense | E14: AUD | F14: =Model!K98 -> 0 | G14: =Model!L98 -> 0 | H14: =Model!M98 -> 0 | I14: =Model!N98 -> 0 | J14: =Model!O98 -> 0 | K14: =Model!P98 -> 0 | L14: =Model!Q98 -> 0 | M14: =Model!R98 -> 0 | ... AP14: =Model!AU98 -> 0
D15: =Model!D99 -> Net profit | E15: AUD | F15: =Model!K99 -> 0 | G15: =Model!L99 -> -4952760 | H15: =Model!M99 -> -4643335.7 | I15: =Model!N99 -> -4315236.1 | J15: =Model!O99 -> -3967306.4 | K15: =Model!P99 -> -3598318 | L15: =Model!Q99 -> 3043427.4 | M15: =Model!R99 -> 2924141 | ... AP15: =Model!AU99 -> 0
A17: Cash Flow Statement
D18: =Model!D206 -> EBITDA | E18: AUD | F18: =Model!K206 -> 0 | G18: =Model!L206 -> 15044301 | H18: =Model!M206 -> 14932807 | I18: =Model!N206 -> 14819875 | J18: =Model!O206 -> 14705447 | K18: =Model!P206 -> 14589463 | L18: =Model!Q206 -> 14471859 | M18: =Model!R206 -> 14352572 | ... AP18: =Model!AU206 -> 0
D19: =Model!D207 -> Total capital expenditure | E19: AUD | F19: =Model!K207 -> -220000000 | G19: =Model!L207 -> 0 | H19: =Model!M207 -> 0 | I19: =Model!N207 -> 0 | J19: =Model!O207 -> 0 | K19: =Model!P207 -> 0 | L19: =Model!Q207 -> 0 | M19: =Model!R207 -> 0 | ... AP19: =Model!AU207 -> 0
D20: =Model!D208 -> Interest during construction | E20: AUD | F20: =Model!K208 -> -8568629.8 | G20: =Model!L208 -> 0 | H20: =Model!M208 -> 0 | I20: =Model!N208 -> 0 | J20: =Model!O208 -> 0 | K20: =Model!P208 -> 0 | L20: =Model!Q208 -> 0 | M20: =Model!R208 -> 0 | ... AP20: =Model!AU208 -> 0
D21: =Model!D209 -> Changes in working capital | E21: AUD | F21: =Model!K209 -> 0 | G21: =Model!L209 -> 0 | H21: =Model!M209 -> 0 | I21: =Model!N209 -> 0 | J21: =Model!O209 -> 0 | K21: =Model!P209 -> 0 | L21: =Model!Q209 -> 0 | M21: =Model!R209 -> 0 | ... AP21: =Model!AU209 -> 0
D22: =Model!D210 -> Tax expense | E22: AUD | F22: =Model!K210 -> 0 | G22: =Model!L210 -> 0 | H22: =Model!M210 -> 0 | I22: =Model!N210 -> 0 | J22: =Model!O210 -> 0 | K22: =Model!P210 -> 0 | L22: =Model!Q210 -> 0 | M22: =Model!R210 -> 0 | ... AP22: =Model!AU210 -> 0
D23: =Model!D211 -> Cash available before debt service | E23: AUD | F23: =Model!K211 -> -2.2856863e+08 | G23: =Model!L211 -> 15044301 | H23: =Model!M211 -> 14932807 | I23: =Model!N211 -> 14819875 | J23: =Model!O211 -> 14705447 | K23: =Model!P211 -> 14589463 | L23: =Model!Q211 -> -81688014 | M23: =Model!R211 -> -67335442 | ... AP23: =Model!AU211 -> 0
D25: =Model!D213 -> Equity contribution | E25: AUD | F25: =Model!K213 -> 96743555 | G25: =Model!L213 -> 0 | H25: =Model!M213 -> 0 | I25: =Model!N213 -> 0 | J25: =Model!O213 -> 0 | K25: =Model!P213 -> 0 | L25: =Model!Q213 -> 0 | M25: =Model!R213 -> 0 | ... AP25: =Model!AU213 -> 0
D26: =Model!D214 -> Debt drawdown | E26: AUD | F26: =Model!K214 -> 1.3182507e+08 | G26: =Model!L214 -> 0 | H26: =Model!M214 -> 0 | I26: =Model!N214 -> 0 | J26: =Model!O214 -> 0 | K26: =Model!P214 -> 0 | L26: =Model!Q214 -> 0 | M26: =Model!R214 -> 0 | ... AP26: =Model!AU214 -> 0
D27: =Model!D215 -> Scheduled repayment | E27: AUD | F27: =Model!K215 -> 0 | G27: =Model!L215 -> -2238585 | H27: =Model!M215 -> -2659503.7 | I27: =Model!N215 -> -3100534.9 | J27: =Model!O215 -> -3562892.6 | K27: =Model!P215 -> -4047865.7 | L27: =Model!Q215 -> 0 | M27: =Model!R215 -> 0 | ... AP27: =Model!AU215 -> 0
D28: =Model!D216 -> Interest paid | E28: AUD | F28: =Model!K216 -> 0 | G28: =Model!L216 -> -8568629.8 | H28: =Model!M216 -> -8147711.2 | I28: =Model!N216 -> -7706680 | J28: =Model!O216 -> -7244322.3 | K28: =Model!P216 -> -6759349.1 | L28: =Model!Q216 -> 0 | M28: =Model!R216 -> 0 | ... AP28: =Model!AU216 -> 0
D29: =Model!D217 -> Cash available for prepayment | E29: AUD | F29: =Model!K217 -> 0 | G29: =Model!L217 -> 4237086.5 | H29: =Model!M217 -> 4125592.2 | I29: =Model!N217 -> 4012660.5 | J29: =Model!O217 -> 3898232.5 | K29: =Model!P217 -> 3782247.7 | L29: =Model!Q217 -> -81688014 | M29: =Model!R217 -> -67335442 | ... AP29: =Model!AU217 -> 0
D31: =Model!D219 -> Cash sweep prepayment | E31: AUD | F31: =Model!K219 -> 0 | G31: =Model!L219 -> -4237086.5 | H31: =Model!M219 -> -4125592.2 | I31: =Model!N219 -> -4012660.5 | J31: =Model!O219 -> -3898232.5 | K31: =Model!P219 -> -3782247.7 | L31: =Model!Q219 -> 0 | M31: =Model!R219 -> 0 | ... AP31: =Model!AU219 -> 0
... D35: =Model!D223 -> Dividends | E35: AUD | F35: =Model!K223 -> 0 | G35: =Model!L223 -> 0 | H35: =Model!M223 -> 0 | I35: =Model!N223 -> 0 | J35: =Model!O223 -> 0 | K35: =Model!P223 -> 0 | L35: =Model!Q223 -> 0 | M35: =Model!R223 -> 0 | ... AP35: =Model!AU223 -> 0
D36: =Model!D227 -> Net cash flow | E36: AUD | F36: =Model!K227 -> 0 | G36: =Model!L227 -> 0 | H36: =Model!M227 -> 0 | I36: =Model!N227 -> 0 | J36: =Model!O227 -> 0 | K36: =Model!P227 -> -96159873 | L36: =Model!Q227 -> 14471859 | M36: =Model!R227 -> 14352572 | ... AP36: =Model!AU227 -> 0
A38: Balance Sheet
C39: Asset | E39: AUD
D40: =Model!D267 -> Cash | E40: AUD | F40: =Model!K267 -> 0 | G40: =Model!L267 -> 0 | H40: =Model!M267 -> 0 | I40: =Model!N267 -> 0 | J40: =Model!O267 -> 0 | K40: =Model!P267 -> -96159873 | L40: =Model!Q267 -> -81688014 | M40: =Model!R267 -> -67335442 | ... AP40: =Model!AU267 -> 0
D41: =Model!D268 -> Account receivables | E41: AUD | F41: =Model!K268 -> 0 | G41: =Model!L268 -> 0 | H41: =Model!M268 -> 0 | I41: =Model!N268 -> 0 | J41: =Model!O268 -> 0 | K41: =Model!P268 -> 0 | L41: =Model!Q268 -> 0 | M41: =Model!R268 -> 0 | ... AP41: =Model!AU268 -> 0
D42: =Model!D269 -> Net plant | E42: AUD | F42: =Model!K269 -> 2.2856863e+08 | G42: =Model!L269 -> 2.171402e+08 | H42: =Model!M269 -> 2.0571177e+08 | I42: =Model!N269 -> 1.9428334e+08 | J42: =Model!O269 -> 1.828549e+08 | K42: =Model!P269 -> 1.7142647e+08 | L42: =Model!Q269 -> 1.5999804e+08 | M42: =Model!R269 -> 1.4856961e+08 | ... AP42: =Model!AU269 -> 0
D43: =Model!D270 -> Total Asset | E43: AUD | F43: =Model!K270 -> 2.2856863e+08 | G43: =Model!L270 -> 2.171402e+08 | H43: =Model!M270 -> 2.0571177e+08 | I43: =Model!N270 -> 1.9428334e+08 | J43: =Model!O270 -> 1.828549e+08 | K43: =Model!P270 -> 75266599 | L43: =Model!Q270 -> 78310027 | M43: =Model!R270 -> 81234168 | ... AP43: =Model!AU270 -> 0
C45: Liability | E45: AUD
D46: =Model!D273 -> Senior debt | E46: AUD | F46: =Model!K273 -> 1.3182507e+08 | G46: =Model!L273 -> 1.253494e+08 | H46: =Model!M273 -> 1.1856431e+08 | I46: =Model!N273 -> 1.1145111e+08 | J46: =Model!O273 -> 1.0398999e+08 | K46: =Model!P273 -> 0 | L46: =Model!Q273 -> 0 | M46: =Model!R273 -> 0 | ... AP46: =Model!AU273 -> 0
D47: =Model!D274 -> Total Liability | E47: AUD | F47: =Model!K274 -> 1.3182507e+08 | G47: =Model!L274 -> 1.253494e+08 | H47: =Model!M274 -> 1.1856431e+08 | I47: =Model!N274 -> 1.1145111e+08 | J47: =Model!O274 -> 1.0398999e+08 | K47: =Model!P274 -> 0 | L47: =Model!Q274 -> 0 | M47: =Model!R274 -> 0 | ... AP47: =Model!AU274 -> 0
C49: Equity | E49: AUD
...
